#usda 1.0
(
    customLayerData = {
        dictionary renderSettings = {
        }
    }
    defaultPrim = "cartpole"
    metersPerUnit = 1
    upAxis = "Z"
)

def SphereLight "SphereLight"
{
    float intensity = 20000
    float radius = 1
    double3 xformOp:translate = (-0.5, 1, 1.5)
    uniform token[] xformOpOrder = ["xformOp:translate"]
}

def PhysicsScene "physicsScene"
{
    float3 gravity = (0, 0, -9.81)
}

def Xform "cartpole" (
    prepend apiSchemas = ["PhysicsArticulationRootAPI", "PhysxArticulationAPI"]
)
{
    bool physxArticulation:enabledSelfCollisions = 0
    int physxArticulation:solverPositionIterationCount = 4
    int physxArticulation:solverVelocityIterationCount = 0

    def Cube "rail" (
        prepend apiSchemas = ["PhysicsCollisionAPI", "PhysicsRigidBodyAPI"]
    )
    {
        double size = 1
        float3 xformOp:scale = (0.02, 6, 0.02)
        uniform token[] xformOpOrder = ["xformOp:scale"]
        color3f[] primvars:displayColor = [(0.9, 0.6, 0.2)]
    }

    def Cube "cart" (
        prepend apiSchemas = ["PhysicsCollisionAPI", "PhysicsRigidBodyAPI", "PhysicsMassAPI"]
    )
    {
        double size = 1
        float3 xformOp:translate = (0, 0, 0)
        float3 xformOp:scale = (0.2, 0.25, 0.2)
        uniform token[] xformOpOrder = ["xformOp:translate", "xformOp:scale"]
        color3f[] primvars:displayColor = [(0.3, 0.5, 0.7)]
    }

    def Cube "pole" (
        prepend apiSchemas = ["PhysicsCollisionAPI", "PhysicsRigidBodyAPI", "PhysicsMassAPI"]
    )
    {
        double size = 1
        float3 xformOp:translate = (0.11, 0, 0.5)
        float3 xformOp:scale = (0.02, 0.04, 1)
        uniform token[] xformOpOrder = ["xformOp:translate", "xformOp:scale"]
        color3f[] primvars:displayColor = [(0.1, 0.1, 0.3)]
    }

    // fixed base
    def PhysicsFixedJoint "rootJoint"
    {
        rel physics:body1 = </cartpole/rail>
    }

    def PhysicsPrismaticJoint "cartJoint"
    {
        rel physics:body0 = </cartpole/rail>
        rel physics:body1 = </cartpole/cart>
        uniform token physics:axis = "Y"
        float physics:lowerLimit = -3
        float physics:upperLimit = 3
    }

    def PhysicsRevoluteJoint "poleJoint"
    {
        rel physics:body0 = </cartpole/cart>
        rel physics:body1 = </cartpole/pole>
        uniform token physics:axis = "X"
        point3f physics:localPos0 = (0.55, 0.0, 0)
        point3f physics:localPos1 = (0, 0, -0.5)
        quatf physics:localRot0 = (1, 0, 0, 0)
        quatf physics:localRot1 = (1, 0, 0, 0)
    }
}
